Workbook

Sheet Převodník
A1: Převodník projekt × kategorie → linka
A2: Linky doplněné Milanem. OP z rozpisů CW43 (list „Linky z rozpisů“). Sdílená linka = počet za celou linku, mezi projekty nesčítat.
A4: Projekt | B4: Kategorie | C4: Strany | D4: Varianty | E4: Počet dílů | F4: Celkem ks CW43/26–CW52/27 | G4: Ø ks/týden Q1 2027 | H4: Linka / pracoviště | I4: Rozpis (skupina) | J4: OP ranní | K4: OP odpolední | L4: OP noční | M4: OP za den | N4: Linku sdílí s (projekt) | O4: Středisko | P4: Norma ks/směnu (8h) | Q4: Poznámka
A5: AU38X | B5: SKIN | C5: LHD, RHD | E5: 2 | F5: 192960 | G5: 5549 | H5: Slush | I5: Slush | J5: =IFERROR(INDEX('Linky z rozpisů'!B:B,MATCH($I5,'Linky z rozpisů'!A:A,0)),"") | K5: =IFERROR(INDEX('Linky z rozpisů'!C:C,MATCH($I5,'Linky z rozpisů'!A:A,0)),"") | L5: =IFERROR(INDEX('Linky z rozpisů'!D:D,MATCH($I5,'Linky z rozpisů'!A:A,0)),"") | M5: =IFERROR(INDEX('Linky z rozpisů'!E:E,MATCH($I5,'Linky z rozpisů'!A:A,0)),"")
A6: G463 M | B6: DP | C6: LHD, RHD | D6: BASIS, BASIS HEAT, SR1, SR1 HEAT, SR2, SR2 HEAT | E6: 405 | F6: 145763 | G6: 3545 | H6: G463 Assembly | I6: G463 Assembly | J6: =IFERROR(INDEX('Linky z rozpisů'!B:B,MATCH($I6,'Linky z rozpisů'!A:A,0)),"") | K6: =IFERROR(INDEX('Linky z rozpisů'!C:C,MATCH($I6,'Linky z rozpisů'!A:A,0)),"") | L6: =IFERROR(INDEX('Linky z rozpisů'!D:D,MATCH($I6,'Linky z rozpisů'!A:A,0)),"") | M6: =IFERROR(INDEX('Linky z rozpisů'!E:E,MATCH($I6,'Linky z rozpisů'!A:A,0)),"")
A7: G463 M | B7: HB | E7: 84 | F7: 50237 | G7: 884 | H7: G463 Assembly | I7: G463 Assembly | J7: =IFERROR(INDEX('Linky z rozpisů'!B:B,MATCH($I7,'Linky z rozpisů'!A:A,0)),"") | K7: =IFERROR(INDEX('Linky z rozpisů'!C:C,MATCH($I7,'Linky z rozpisů'!A:A,0)),"") | L7: =IFERROR(INDEX('Linky z rozpisů'!D:D,MATCH($I7,'Linky z rozpisů'!A:A,0)),"") | M7: =IFERROR(INDEX('Linky z rozpisů'!E:E,MATCH($I7,'Linky z rozpisů'!A:A,0)),"")
A8: OV51/52 | B8: END CAP | C8: LHD, RHD | E8: 2 | F8: 32256 | G8: 1499 | H8: IMM | I8: IMM | J8: =IFERROR(INDEX('Linky z rozpisů'!B:B,MATCH($I8,'Linky z rozpisů'!A:A,0)),"") | K8: =IFERROR(INDEX('Linky z rozpisů'!C:C,MATCH($I8,'Linky z rozpisů'!A:A,0)),"") | L8: =IFERROR(INDEX('Linky z rozpisů'!D:D,MATCH($I8,'Linky z rozpisů'!A:A,0)),"") | M8: =IFERROR(INDEX('Linky z rozpisů'!E:E,MATCH($I8,'Linky z rozpisů'!A:A,0)),"")
A9: OV51/52 | B9: IP | C9: LHD, RHD | D9: HUD | E9: 4 | F9: 16024 | G9: 748 | H9: OV51 IP assembly | I9: OV51/64 | J9: =IFERROR(INDEX('Linky z rozpisů'!B:B,MATCH($I9,'Linky z rozpisů'!A:A,0)),"") | K9: =IFERROR(INDEX('Linky z rozpisů'!C:C,MATCH($I9,'Linky z rozpisů'!A:A,0)),"") | L9: =IFERROR(INDEX('Linky z rozpisů'!D:D,MATCH($I9,'Linky z rozpisů'!A:A,0)),"") | M9: =IFERROR(INDEX('Linky z rozpisů'!E:E,MATCH($I9,'Linky z rozpisů'!A:A,0)),"") | N9: OV64
A10: OV64 | B10: IP | C10: LHD, RHD | D10: HUD | E10: 4 | F10: 26288 | G10: 1182 | H10: OV64 IP Assembly | I10: OV51/64 | J10: =IFERROR(INDEX('Linky z rozpisů'!B:B,MATCH($I10,'Linky z rozpisů'!A:A,0)),"") | K10: =IFERROR(INDEX('Linky z rozpisů'!C:C,MATCH($I10,'Linky z rozpisů'!A:A,0)),"") | L10: =IFERROR(INDEX('Linky z rozpisů'!D:D,MATCH($I10,'Linky z rozpisů'!A:A,0)),"") | M10: =IFERROR(INDEX('Linky z rozpisů'!E:E,MATCH($I10,'Linky z rozpisů'!A:A,0)),"") | N10: OV51
A11: OV64 | B11: GVBX | C11: RHD | E11: 1 | F11: 3030 | G11: 196 | H11: OV64 GB | I11: GB/DP | J11: =IFERROR(INDEX('Linky z rozpisů'!B:B,MATCH($I11,'Linky z rozpisů'!A:A,0)),"") | K11: =IFERROR(INDEX('Linky z rozpisů'!C:C,MATCH($I11,'Linky z rozpisů'!A:A,0)),"") | L11: =IFERROR(INDEX('Linky z rozpisů'!D:D,MATCH($I11,'Linky z rozpisů'!A:A,0)),"") | M11: =IFERROR(INDEX('Linky z rozpisů'!E:E,MATCH($I11,'Linky z rozpisů'!A:A,0)),"") | Q11: rozpis GB/DP – ověřit, že sem patří
A12: PO455 | B12: STRUCTURE | C12: LHD, RHD | E12: 4 | F12: 2837 | G12: 14 | H12: PO455 | Q12: rozpis nenalezen
A13: PO455 | B13: IP | C13: LHD | E13: 2 | F13: 56 | G13: 3 | H13: PO455 | N13: W206 / SK336 | Q13: rozpis nenalezen
A14: SK336/1 | B14: IP | C14: LHD, RHD | D14: HUD | E14: 4 | F14: 114451 | G14: 2492 | H14: SK336 Assembly | I14: SK336/W206 | J14: =IFERROR(INDEX('Linky z rozpisů'!B:B,MATCH($I14,'Linky z rozpisů'!A:A,0)),"") | K14: =IFERROR(INDEX('Linky z rozpisů'!C:C,MATCH($I14,'Linky z rozpisů'!A:A,0)),"") | L14: =IFERROR(INDEX('Linky z rozpisů'!D:D,MATCH($I14,'Linky z rozpisů'!A:A,0)),"") | M14: =IFERROR(INDEX('Linky z rozpisů'!E:E,MATCH($I14,'Linky z rozpisů'!A:A,0)),"") | N14: W206 / SK336
A15: SK371 | B15: SKIN | C15: LHD, RHD | E15: 2 | F15: 110600 | G15: 2973 | H15: Slush | I15: Slush | J15: =IFERROR(INDEX('Linky z rozpisů'!B:B,MATCH($I15,'Linky z rozpisů'!A:A,0)),"") | K15: =IFERROR(INDEX('Linky z rozpisů'!C:C,MATCH($I15,'Linky z rozpisů'!A:A,0)),"") | L15: =IFERROR(INDEX('Linky z rozpisů'!D:D,MATCH($I15,'Linky z rozpisů'!A:A,0)),"") | M15: =IFERROR(INDEX('Linky z rozpisů'!E:E,MATCH($I15,'Linky z rozpisů'!A:A,0)),"")
A16: V530 | B16: IP | C16: LHD, RHD | D16: HUD | E16: 25 | F16: 13446 | G16: 15 | H16: MBEAM assembly | I16: MBEAM | J16: =IFERROR(INDEX('Linky z rozpisů'!B:B,MATCH($I16,'Linky z rozpisů'!A:A,0)),"") | K16: =IFERROR(INDEX('Linky z rozpisů'!C:C,MATCH($I16,'Linky z rozpisů'!A:A,0)),"") | L16: =IFERROR(INDEX('Linky z rozpisů'!D:D,MATCH($I16,'Linky z rozpisů'!A:A,0)),"") | M16: =IFERROR(INDEX('Linky z rozpisů'!E:E,MATCH($I16,'Linky z rozpisů'!A:A,0)),"") | N16: X540 / W520
A17: W177 | B17: IP | C17: LHD, RHD | D17: HUD | E17: 20 | F17: 69713 | G17: 1427 | H17: W177 IP Assembly | I17: W177/W247 IP (MFA2) | J17: =IFERROR(INDEX('Linky z rozpisů'!B:B,MATCH($I17,'Linky z rozpisů'!A:A,0)),"") | K17: =IFERROR(INDEX('Linky z rozpisů'!C:C,MATCH($I17,'Linky z rozpisů'!A:A,0)),"") | L17: =IFERROR(INDEX('Linky z rozpisů'!D:D,MATCH($I17,'Linky z rozpisů'!A:A,0)),"") | M17: =IFERROR(INDEX('Linky z rozpisů'!E:E,MATCH($I17,'Linky z rozpisů'!A:A,0)),"") | N17: W247 IP
A18: W177 | B18: GVBX | C18: LHD, RHD | E18: 5 | F18: 69499 | G18: 1420 | H18: W177 GB | I18: GB/DP | J18: =IFERROR(INDEX('Linky z rozpisů'!B:B,MATCH($I18,'Linky z rozpisů'!A:A,0)),"") | K18: =IFERROR(INDEX('Linky z rozpisů'!C:C,MATCH($I18,'Linky z rozpisů'!A:A,0)),"") | L18: =IFERROR(INDEX('Linky z rozpisů'!D:D,MATCH($I18,'Linky z rozpisů'!A:A,0)),"") | M18: =IFERROR(INDEX('Linky z rozpisů'!E:E,MATCH($I18,'Linky z rozpisů'!A:A,0)),"") | N18: W247 GB / OV64 GB | Q18: rozpis GB/DP – ověřit, že sem patří
A19: W177 | B19: DECO | C19: LHD, RHD | E19: 8 | F19: 15919 | G19: 371 | H19: W177 DP | Q19: rozpis nenalezen – patří do GB/DP?
A20: W206 | B20: SKIN | C20: LHD, RHD | E20: 2 | F20: 23508 | G20: 310 | H20: Slush | I20: Slush | J20: =IFERROR(INDEX('Linky z rozpisů'!B:B,MATCH($I20,'Linky z rozpisů'!A:A,0)),"") | K20: =IFERROR(INDEX('Linky z rozpisů'!C:C,MATCH($I20,'Linky z rozpisů'!A:A,0)),"") | L20: =IFERROR(INDEX('Linky z rozpisů'!D:D,MATCH($I20,'Linky z rozpisů'!A:A,0)),"") | M20: =IFERROR(INDEX('Linky z rozpisů'!E:E,MATCH($I20,'Linky z rozpisů'!A:A,0)),"")
A21: W206 | B21: IP | C21: LHD, RHD | D21: HUD | E21: 9 | F21: 14623 | G21: 308 | H21: W206 IP assembly | I21: SK336/W206 | J21: =IFERROR(INDEX('Linky z rozpisů'!B:B,MATCH($I21,'Linky z rozpisů'!A:A,0)),"") | K21: =IFERROR(INDEX('Linky z rozpisů'!C:C,MATCH($I21,'Linky z rozpisů'!A:A,0)),"") | L21: =IFERROR(INDEX('Linky z rozpisů'!D:D,MATCH($I21,'Linky z rozpisů'!A:A,0)),"") | M21: =IFERROR(INDEX('Linky z rozpisů'!E:E,MATCH($I21,'Linky z rozpisů'!A:A,0)),"") | N21: SK336 / PO455
A22: W247 | B22: GVBX | C22: LHD, RHD | E22: 4 | F22: 3612 | G22: 16 | H22: W247 GB | I22: GB/DP | J22: =IFERROR(INDEX('Linky z rozpisů'!B:B,MATCH($I22,'Linky z rozpisů'!A:A,0)),"") | K22: =IFERROR(INDEX('Linky z rozpisů'!C:C,MATCH($I22,'Linky z rozpisů'!A:A,0)),"") | L22: =IFERROR(INDEX('Linky z rozpisů'!D:D,MATCH($I22,'Linky z rozpisů'!A:A,0)),"") | M22: =IFERROR(INDEX('Linky z rozpisů'!E:E,MATCH($I22,'Linky z rozpisů'!A:A,0)),"") | N22: W177 GB / OV64 GB | Q22: rozpis GB/DP – ověřit, že sem patří
A23: W247 | B23: IP | C23: LHD, RHD | D23: HUD | E23: 12 | F23: 2996 | G23: 3 | H23: W247 IP Assembly | I23: W177/W247 IP (MFA2) | J23: =IFERROR(INDEX('Linky z rozpisů'!B:B,MATCH($I23,'Linky z rozpisů'!A:A,0)),"") | K23: =IFERROR(INDEX('Linky z rozpisů'!C:C,MATCH($I23,'Linky z rozpisů'!A:A,0)),"") | L23: =IFERROR(INDEX('Linky z rozpisů'!D:D,MATCH($I23,'Linky z rozpisů'!A:A,0)),"") | M23: =IFERROR(INDEX('Linky z rozpisů'!E:E,MATCH($I23,'Linky z rozpisů'!A:A,0)),"") | N23: W177 IP
A24: W520 | B24: IP | C24: LHD, RHD | D24: HUD | E24: 62 | F24: 51850 | G24: 1084 | H24: MBEAM assembly | I24: MBEAM | J24: =IFERROR(INDEX('Linky z rozpisů'!B:B,MATCH($I24,'Linky z rozpisů'!A:A,0)),"") | K24: =IFERROR(INDEX('Linky z rozpisů'!C:C,MATCH($I24,'Linky z rozpisů'!A:A,0)),"") | L24: =IFERROR(INDEX('Linky z rozpisů'!D:D,MATCH($I24,'Linky z rozpisů'!A:A,0)),"") | M24: =IFERROR(INDEX('Linky z rozpisů'!E:E,MATCH($I24,'Linky z rozpisů'!A:A,0)),"") | N24: X540 / V530
A25: W520 | B25: bez kategorie | E25: 2 | F25: 6 | G25: 0
A26: X540 | B26: IP | C26: LHD, RHD | D26: HUD | E26: 56 | F26: 144143 | G26: 2427 | H26: MBEAM assembly | I26: MBEAM | J26: =IFERROR(INDEX('Linky z rozpisů'!B:B,MATCH($I26,'Linky z rozpisů'!A:A,0)),"") | K26: =IFERROR(INDEX('Linky z rozpisů'!C:C,MATCH($I26,'Linky z rozpisů'!A:A,0)),"") | L26: =IFERROR(INDEX('Linky z rozpisů'!D:D,MATCH($I26,'Linky z rozpisů'!A:A,0)),"") | M26: =IFERROR(INDEX('Linky z rozpisů'!E:E,MATCH($I26,'Linky z rozpisů'!A:A,0)),"") | N26: V530 / W520

Sheet Normy
A1: Normy po linkách – doplnit (žluté)
A2: Norma = dobré kusy za 8h směnu při 100 % OEE (dle IE / routingu). OP standard = počet operátorů na směnu podle balancingu. Skutečnost OP doplnit později.
A4: Linka | B4: Projekty | C4: Norma ks/8h | D4: Plán OEE | E4: OP standard na směnu | F4: Max směn/týden | G4: Skutečnost OP za den (doplnit později) | H4: Owner normy
A5: Slush | B5: AU38X SKIN, SK371 SKIN, W206 SKIN | F5: 15 | H5: David Varhan
A6: G463 Assembly | B6: G463 M DP, G463 M HB | F6: 15 | H6: David Varhan
A7: IMM | B7: OV51/52 END CAP | F7: 15 | H7: David Varhan
A8: OV51/64 | B8: OV51/52 IP, OV64 IP | F8: 15 | H8: David Varhan
A9: GB/DP | B9: OV64 GVBX, W177 GVBX, W247 GVBX | F9: 15 | H9: David Varhan
A10: SK336/W206 | B10: SK336/1 IP, W206 IP | F10: 15 | H10: David Varhan
A11: MBEAM | B11: V530 IP, W520 IP, X540 IP | F11: 15 | H11: David Varhan
A12: W177/W247 IP | B12: W177 IP, W247 IP | F12: 15 | H12: David Varhan
A13: W177 DP | B13: W177 DECO | F13: 15 | H13: David Varhan
A14: PO455 | B14: PO455 IP, PO455 STRUCTURE | F14: 15 | H14: David Varhan

Sheet Parametry
A1: Parametry výpočtu FTE
A3: Parametr | B3: Hodnota | C3: Poznámka
A4: Hodin na FTE za týden | B4: 37.5 | C4: smluvní týdenní fond
A5: Absence + dovolená | B5: 0.1 | C5: podíl, doplnit z HR
A6: Délka směny (h) | B6: 8 | C6: normy se zadávají na 8h směnu
A7: Výchozí plán OEE | B7: 0.85 | C7: použije se, když u linky OEE chybí

Sheet Volume po lince
A1: Volume po lince z odvolávek CW43/2026 (ks/týden, hotové díly)
A3: Linka | B3: CW 43 | C3: CW 44 | D3: CW 45 | E3: CW 46 | F3: CW 47 | G3: CW 48 | H3: CW 49 | I3: CW 50 | J3: CW 51 | K3: CW 52 | L3: CW 53 | M3: CW 1/2027 | N3: CW 2/2027 | O3: CW 3/2027 | P3: CW 4/2027 | Q3: CW 5/2027 | R3: CW 6/2027 | S3: CW 7/2027 | T3: CW 8/2027 | U3: CW 9/2027 | V3: CW 10/2027 | W3: CW 11/2027 | X3: CW 12/2027 | Y3: CW 13/2027 | Z3: CW 14/2027 | AA3: CW 15/2027 | AB3: CW 16/2027 | AC3: CW 17/2027 | AD3: CW 18/2027 | AE3: CW 19/2027 | AF3: CW 20/2027 | AG3: CW 21/2027 | AH3: CW 22/2027 | AI3: CW 23/2027 | AJ3: CW 24/2027 | AK3: CW 25/2027 | AL3: CW 26/2027 | AM3: CW 27/2027 | AN3: CW 28/2027 | AO3: CW 29/2027 | AP3: CW 30/2027 | AQ3: CW 31/2027 | AR3: CW 32/2027 | AS3: CW 33/2027 | AT3: CW 34/2027 | AU3: CW 35/2027 | AV3: CW 36/2027 | AW3: CW 37/2027 | AX3: CW 38/2027 | AY3: CW 39/2027 | AZ3: CW 40/2027 | BA3: CW 41/2027 | BB3: CW 42/2027 | BC3: CW 43/2027 | BD3: CW 44/2027 | BE3: CW 45/2027 | BF3: CW 46/2027 | BG3: CW 47/2027 | BH3: CW 48/2027 | BI3: CW 49/2027 | BJ3: CW 50/2027 | BK3: CW 51/2027 | BL3: CW 52/2027 | BM3: Celkem
A4: Slush | B4: 6800 | C4: 9332 | D4: 6200 | E4: 7250 | F4: 7600 | G4: 8768 | H4: 7918 | I4: 8554 | J4: 6090 | K4: 3068 | L4: 0 | M4: 7660 | N4: 7640 | O4: 7610 | P4: 8654 | Q4: 8672 | R4: 8480 | S4: 8575 | T4: 8479 | U4: 9772 | V4: 9772 | W4: 9772 | X4: 9772 | Y4: 9964 | Z4: 7199 | AA4: 7487 | AB4: 7485 | AC4: 7485 | AD4: 8504 | AE4: 8408 | AF4: 8312 | AG4: 8312 | AH4: 8600 | AI4: 7923 | AJ4: 7923 | AK4: 7921 | AL4: 7633 | AM4: 2213 | AN4: 2501 | AO4: 2884 | AP4: 2788 | AQ4: 6172 | AR4: 6172 | AS4: 6172 | AT4: 6076 | AU4: 672 | AV4: 672 | AW4: 576 | AX4: 480 | AY4: 0 | AZ4: 0 | BA4: 0 | BB4: 0 | BC4: 96 | BD4: 0 | BE4: 0 | BF4: 0 | BG4: 0 | BH4: 0 | BI4: 0 | BJ4: 0 | BK4: 0 | BL4: 0 | BM4: =SUM(B4:BL4)
A5: G463 Assembly | B5: 4672 | C5: 3767 | D5: 4677 | E5: 4847 | F5: 4602 | G5: 4987 | H5: 4485 | I5: 2699 | J5: 4433 | K5: 1813 | L5: 1337 | M5: 1854 | N5: 4675 | O5: 4682 | P5: 0 | Q5: 5123 | R5: 5012 | S5: 4890 | T5: 4762 | U5: 5486 | V5: 5353 | W5: 5264 | X5: 5148 | Y5: 5317 | Z5: 5182 | AA5: 5071 | AB5: 4982 | AC5: 3944 | AD5: 3784 | AE5: 3695 | AF5: 3600 | AG5: 0 | AH5: 5340 | AI5: 5181 | AJ5: 5073 | AK5: 4977 | AL5: 4080 | AM5: 3944 | AN5: 3841 | AO5: 3745 | AP5: 2670 | AQ5: 2575 | AR5: 2482 | AS5: 2409 | AT5: 0 | AU5: 1343 | AV5: 1323 | AW5: 1304 | AX5: 1281 | AY5: 1168 | AZ5: 1143 | BA5: 1121 | BB5: 1105 | BC5: 0 | BD5: 1273 | BE5: 1240 | BF5: 1222 | BG5: 1206 | BH5: 978 | BI5: 943 | BJ5: 923 | BK5: 908 | BL5: 1059 | BM5: =SUM(B5:BL5)
A6: IMM | B6: 0 | C6: 448 | D6: 1792 | E6: 1792 | F6: 1792 | G6: 1792 | H6: 1792 | I6: 1792 | J6: 1344 | K6: 0 | L6: 224 | M6: 1792 | N6: 1568 | O6: 1792 | P6: 1792 | Q6: 1568 | R6: 1792 | S6: 1568 | T6: 1792 | U6: 1792 | V6: 1568 | W6: 1568 | X6: 896 | Y6: 0 | Z6: 0 | AA6: 0 | AB6: 0 | AC6: 0 | AD6: 0 | AE6: 0 | AF6: 0 | AG6: 0 | AH6: 0 | AI6: 0 | AJ6: 0 | AK6: 0 | AL6: 0 | AM6: 0 | AN6: 0 | AO6: 0 | AP6: 0 | AQ6: 0 | AR6: 0 | AS6: 0 | AT6: 0 | AU6: 0 | AV6: 0 | AW6: 0 | AX6: 0 | AY6: 0 | AZ6: 0 | BA6: 0 | BB6: 0 | BC6: 0 | BD6: 0 | BE6: 0 | BF6: 0 | BG6: 0 | BH6: 0 | BI6: 0 | BJ6: 0 | BK6: 0 | BL6: 0 | BM6: =SUM(B6:BL6)
A7: OV51/64 | B7: 1096 | C7: 464 | D7: 2072 | E7: 2088 | F7: 2128 | G7: 2104 | H7: 2408 | I7: 2040 | J7: 1864 | K7: 536 | L7: 424 | M7: 2032 | N7: 2072 | O7: 2056 | P7: 2344 | Q7: 2344 | R7: 2032 | S7: 2064 | T7: 2336 | U7: 2024 | V7: 2368 | W7: 2064 | X7: 1352 | Y7: 0 | Z7: 0 | AA7: 0 | AB7: 0 | AC7: 0 | AD7: 0 | AE7: 0 | AF7: 0 | AG7: 0 | AH7: 0 | AI7: 0 | AJ7: 0 | AK7: 0 | AL7: 0 | AM7: 0 | AN7: 0 | AO7: 0 | AP7: 0 | AQ7: 0 | AR7: 0 | AS7: 0 | AT7: 0 | AU7: 0 | AV7: 0 | AW7: 0 | AX7: 0 | AY7: 0 | AZ7: 0 | BA7: 0 | BB7: 0 | BC7: 0 | BD7: 0 | BE7: 0 | BF7: 0 | BG7: 0 | BH7: 0 | BI7: 0 | BJ7: 0 | BK7: 0 | BL7: 0 | BM7: =SUM(B7:BL7)
A8: GB/DP | B8: 3704 | C8: 2007 | D8: 1441 | E8: 1469 | F8: 1666 | G8: 1580 | H8: 1720 | I8: 1956 | J8: 1814 | K8: 30 | L8: 54 | M8: 495 | N8: 1610 | O8: 1641 | P8: 1660 | Q8: 1766 | R8: 1780 | S8: 1762 | T8: 1766 | U8: 1677 | V8: 1766 | W8: 1795 | X8: 1706 | Y8: 1793 | Z8: 1785 | AA8: 1729 | AB8: 1728 | AC8: 1451 | AD8: 1451 | AE8: 1450 | AF8: 1449 | AG8: 53 | AH8: 1646 | AI8: 1646 | AJ8: 1658 | AK8: 1644 | AL8: 1735 | AM8: 1689 | AN8: 1685 | AO8: 1736 | AP8: 1607 | AQ8: 1651 | AR8: 1603 | AS8: 1607 | AT8: 0 | AU8: 1593 | AV8: 1591 | AW8: 1653 | AX8: 1590 | AY8: 53 | AZ8: 0 | BA8: 0 | BB8: 0 | BC8: 0 | BD8: 0 | BE8: 0 | BF8: 0 | BG8: 0 | BH8: 0 | BI8: 0 | BJ8: 0 | BK8: 0 | BL8: 0 | BM8: =SUM(B8:BL8)
A9: SK336/W206 | B9: 1200 | C9: 2336 | D9: 3199 | E9: 3107 | F9: 2114 | G9: 3100 | H9: 3246 | I9: 3264 | J9: 2999 | K9: 860 | L9: 0 | M9: 2717 | N9: 2963 | O9: 2997 | P9: 2957 | Q9: 2939 | R9: 2917 | S9: 2965 | T9: 2938 | U9: 2879 | V9: 2857 | W9: 2710 | X9: 2071 | Y9: 2490 | Z9: 10100 | AA9: 295 | AB9: 317 | AC9: 312 | AD9: 10221 | AE9: 307 | AF9: 315 | AG9: 42 | AH9: 12858 | AI9: 288 | AJ9: 310 | AK9: 291 | AL9: 367 | AM9: 6444 | AN9: 321 | AO9: 331 | AP9: 277 | AQ9: 7883 | AR9: 312 | AS9: 265 | AT9: 0 | AU9: 12366 | AV9: 274 | AW9: 268 | AX9: 269 | AY9: 375 | AZ9: 277 | BA9: 274 | BB9: 270 | BC9: 0 | BD9: 257 | BE9: 257 | BF9: 254 | BG9: 252 | BH9: 0 | BI9: 0 | BJ9: 0 | BK9: 0 | BL9: 0 | BM9: =SUM(B9:BL9)
A10: MBEAM | B10: 3511 | C10: 3762 | D10: 3191 | E10: 3656 | F10: 4102 | G10: 3325 | H10: 4220 | I10: 4337 | J10: 3827 | K10: 1336 | L10: 0 | M10: 2017 | N10: 2485 | O10: 3300 | P10: 3016 | Q10: 3628 | R10: 3934 | S10: 3834 | T10: 3328 | U10: 4033 | V10: 4007 | W10: 4005 | X10: 3920 | Y10: 4333 | Z10: 4310 | AA10: 4280 | AB10: 4250 | AC10: 3735 | AD10: 3697 | AE10: 3659 | AF10: 3652 | AG10: 72 | AH10: 4361 | AI10: 4348 | AJ10: 4323 | AK10: 4295 | AL10: 3635 | AM10: 3621 | AN10: 3575 | AO10: 3578 | AP10: 3076 | AQ10: 3025 | AR10: 3530 | AS10: 2970 | AT10: 0 | AU10: 3155 | AV10: 3119 | AW10: 3077 | AX10: 3051 | AY10: 3645 | AZ10: 3610 | BA10: 3573 | BB10: 3543 | BC10: 0 | BD10: 4136 | BE10: 4100 | BF10: 4066 | BG10: 4040 | BH10: 2709 | BI10: 2677 | BJ10: 2645 | BK10: 2607 | BL10: 2587 | BM10: =SUM(B10:BL10)
A11: W177/W247 IP | B11: 3652 | C11: 2006 | D11: 1386 | E11: 1482 | F11: 1661 | G11: 1566 | H11: 1657 | I11: 1824 | J11: 1537 | K11: 19 | L11: 25 | M11: 357 | N11: 1403 | O11: 1407 | P11: 1388 | Q11: 1526 | R11: 1521 | S11: 1537 | T11: 1549 | U11: 1532 | V11: 1540 | W11: 1571 | X11: 1521 | Y11: 1742 | Z11: 1735 | AA11: 1728 | AB11: 1734 | AC11: 1476 | AD11: 1451 | AE11: 1451 | AF11: 1448 | AG11: 0 | AH11: 1664 | AI11: 1669 | AJ11: 1653 | AK11: 1650 | AL11: 1724 | AM11: 1690 | AN11: 1689 | AO11: 1681 | AP11: 1608 | AQ11: 1605 | AR11: 1603 | AS11: 1635 | AT11: 3 | AU11: 1605 | AV11: 1593 | AW11: 1585 | AX11: 1587 | AY11: 31 | AZ11: 2 | BA11: 0 | BB11: 0 | BC11: 0 | BD11: 0 | BE11: 0 | BF11: 0 | BG11: 0 | BH11: 0 | BI11: 0 | BJ11: 0 | BK11: 0 | BL11: 0 | BM11: =SUM(B11:BL11)
A12: W177 DP | B12: 201 | C12: 465 | D12: 355 | E12: 204 | F12: 397 | G12: 211 | H12: 360 | I12: 404 | J12: 337 | K12: 0 | L12: 0 | M12: 57 | N12: 191 | O12: 352 | P12: 300 | Q12: 356 | R12: 437 | S12: 429 | T12: 483 | U12: 435 | V12: 433 | W12: 432 | X12: 430 | Y12: 484 | Z12: 481 | AA12: 479 | AB12: 478 | AC12: 366 | AD12: 364 | AE12: 364 | AF12: 363 | AG12: 0 | AH12: 467 | AI12: 466 | AJ12: 463 | AK12: 463 | AL12: 362 | AM12: 358 | AN12: 358 | AO12: 356 | AP12: 369 | AQ12: 369 | AR12: 367 | AS12: 364 | AT12: 0 | AU12: 130 | AV12: 128 | AW12: 126 | AX12: 125 | AY12: 0 | AZ12: 0 | BA12: 0 | BB12: 0 | BC12: 0 | BD12: 0 | BE12: 0 | BF12: 0 | BG12: 0 | BH12: 0 | BI12: 0 | BJ12: 0 | BK12: 0 | BL12: 0 | BM12: =SUM(B12:BL12)
A13: PO455 | B13: 4 | C13: 3 | D13: 3 | E13: 12 | F13: 30 | G13: 6 | H13: 8 | I13: 0 | J13: 0 | K13: 0 | L13: 0 | M13: 0 | N13: 17 | O13: 26 | P13: 51 | Q13: 30 | R13: 0 | S13: 8 | T13: 4 | U13: 12 | V13: 14 | W13: 18 | X13: 17 | Y13: 17 | Z13: 32 | AA13: 53 | AB13: 34 | AC13: 59 | AD13: 53 | AE13: 107 | AF13: 0 | AG13: 58 | AH13: 92 | AI13: 97 | AJ13: 92 | AK13: 90 | AL13: 116 | AM13: 129 | AN13: 133 | AO13: 141 | AP13: 151 | AQ13: 0 | AR13: 0 | AS13: 0 | AT13: 155 | AU13: 178 | AV13: 190 | AW13: 206 | AX13: 217 | AY13: 230 | AZ13: 0 | BA13: 0 | BB13: 0 | BC13: 0 | BD13: 0 | BE13: 0 | BF13: 0 | BG13: 0 | BH13: 0 | BI13: 0 | BJ13: 0 | BK13: 0 | BL13: 0 | BM13: =SUM(B13:BL13)

Sheet Potřeba FTE
A1: Potřeba DL podle volume (počítá se po doplnění norem)
A2: Směny = ROUNDUP(volume / (norma × OEE)). FTE = směny × OP × 8 h / (h na FTE × (1 − absence)). Červeně = víc směn, než linka může jet.
A3: Skutečnost FTE = Normy!G (lidí za den) × 5 dní × 8 h přepočteno stejně jako potřeba. Jen orientačně – 12h směny podhodnotí; později nahradit Summary PLANA1.
A4: Linka | B4: Ukazatel | C4: CW 43 | D4: CW 44 | E4: CW 45 | F4: CW 46 | G4: CW 47 | H4: CW 48 | I4: CW 49 | J4: CW 50 | K4: CW 51 | L4: CW 52 | M4: CW 53 | N4: CW 1/2027 | O4: CW 2/2027 | P4: CW 3/2027 | Q4: CW 4/2027 | R4: CW 5/2027 | S4: CW 6/2027 | T4: CW 7/2027 | U4: CW 8/2027 | V4: CW 9/2027 | W4: CW 10/2027 | X4: CW 11/2027 | Y4: CW 12/2027 | Z4: CW 13/2027 | AA4: CW 14/2027 | AB4: CW 15/2027 | AC4: CW 16/2027 | AD4: CW 17/2027 | AE4: CW 18/2027 | AF4: CW 19/2027 | AG4: CW 20/2027 | AH4: CW 21/2027 | AI4: CW 22/2027 | AJ4: CW 23/2027 | AK4: CW 24/2027 | AL4: CW 25/2027 | AM4: CW 26/2027 | AN4: CW 27/2027 | AO4: CW 28/2027 | AP4: CW 29/2027 | AQ4: CW 30/2027 | AR4: CW 31/2027 | AS4: CW 32/2027 | AT4: CW 33/2027 | AU4: CW 34/2027 | AV4: CW 35/2027 | AW4: CW 36/2027 | AX4: CW 37/2027 | AY4: CW 38/2027 | AZ4: CW 39/2027 | BA4: CW 40/2027 | BB4: CW 41/2027 | BC4: CW 42/2027 | BD4: CW 43/2027 | BE4: CW 44/2027 | BF4: CW 45/2027 | BG4: CW 46/2027 | BH4: CW 47/2027 | BI4: CW 48/2027 | BJ4: CW 49/2027 | BK4: CW 50/2027 | BL4: CW 51/2027 | BM4: CW 52/2027
A5: Slush | B5: Potřebné směny (8h) | C5: =IF(OR(Normy!$C$5="",'Volume po lince'!B4=0),"",ROUNDUP('Volume po lince'!B4/(Normy!$C$5*IF(Normy!$D$5="",Parametry!$B$7,Normy!$D$5)),0)) | D5: =IF(OR(Normy!$C$5="",'Volume po lince'!C4=0),"",ROUNDUP('Volume po lince'!C4/(Normy!$C$5*IF(Normy!$D$5="",Parametry!$B$7,Normy!$D$5)),0)) | E5: =IF(OR(Normy!$C$5="",'Volume po lince'!D4=0),"",ROUNDUP('Volume po lince'!D4/(Normy!$C$5*IF(Normy!$D$5="",Parametry!$B$7,Normy!$D$5)),0)) | F5: =IF(OR(Normy!$C$5="",'Volume po lince'!E4=0),"",ROUNDUP('Volume po lince'!E4/(Normy!$C$5*IF(Normy!$D$5="",Parametry!$B$7,Normy!$D$5)),0)) | G5: =IF(OR(Normy!$C$5="",'Volume po lince'!F4=0),"",ROUNDUP('Volume po lince'!F4/(Normy!$C$5*IF(Normy!$D$5="",Parametry!$B$7,Normy!$D$5)),0)) | H5: =IF(OR(Normy!$C$5="",'Volume po lince'!G4=0),"",ROUNDUP('Volume po lince'!G4/(Normy!$C$5*IF(Normy!$D$5="",Parametry!$B$7,Normy!$D$5)),0)) | I5: =IF(OR(Normy!$C$5="",'Volume po lince'!H4=0),"",ROUNDUP('Volume po lince'!H4/(Normy!$C$5*IF(Normy!$D$5="",Parametry!$B$7,Normy!$D$5)),0)) | J5: =IF(OR(Normy!$C$5="",'Volume po lince'!I4=0),"",ROUNDUP('Volume po lince'!I4/(Normy!$C$5*IF(Normy!$D$5="",Parametry!$B$7,Normy!$D$5)),0)) | ... BM5: =IF(OR(Normy!$C$5="",'Volume po lince'!BL4=0),"",ROUNDUP('Volume po lince'!BL4/(Normy!$C$5*IF(Normy!$D$5="",Parametry!$B$7,Normy!$D$5)),0))
B6: OP-směn | C6: =IF(OR(C5="",Normy!$E$5=""),"",C5*Normy!$E$5) | D6: =IF(OR(D5="",Normy!$E$5=""),"",D5*Normy!$E$5) | E6: =IF(OR(E5="",Normy!$E$5=""),"",E5*Normy!$E$5) | F6: =IF(OR(F5="",Normy!$E$5=""),"",F5*Normy!$E$5) | G6: =IF(OR(G5="",Normy!$E$5=""),"",G5*Normy!$E$5) | H6: =IF(OR(H5="",Normy!$E$5=""),"",H5*Normy!$E$5) | I6: =IF(OR(I5="",Normy!$E$5=""),"",I5*Normy!$E$5) | J6: =IF(OR(J5="",Normy!$E$5=""),"",J5*Normy!$E$5) | ... BM6: =IF(OR(BM5="",Normy!$E$5=""),"",BM5*Normy!$E$5)
B7: Potřeba FTE DL | C7: =IF(C6="","",ROUND(C6*Parametry!$B$6/(Parametry!$B$4*(1-Parametry!$B$5)),1)) | D7: =IF(D6="","",ROUND(D6*Parametry!$B$6/(Parametry!$B$4*(1-Parametry!$B$5)),1)) | E7: =IF(E6="","",ROUND(E6*Parametry!$B$6/(Parametry!$B$4*(1-Parametry!$B$5)),1)) | F7: =IF(F6="","",ROUND(F6*Parametry!$B$6/(Parametry!$B$4*(1-Parametry!$B$5)),1)) | G7: =IF(G6="","",ROUND(G6*Parametry!$B$6/(Parametry!$B$4*(1-Parametry!$B$5)),1)) | H7: =IF(H6="","",ROUND(H6*Parametry!$B$6/(Parametry!$B$4*(1-Parametry!$B$5)),1)) | I7: =IF(I6="","",ROUND(I6*Parametry!$B$6/(Parametry!$B$4*(1-Parametry!$B$5)),1)) | J7: =IF(J6="","",ROUND(J6*Parametry!$B$6/(Parametry!$B$4*(1-Parametry!$B$5)),1)) | ... BM7: =IF(BM6="","",ROUND(BM6*Parametry!$B$6/(Parametry!$B$4*(1-Parametry!$B$5)),1))
B8: Skutečnost FTE | C8: =IF(Normy!$G$5="","",ROUND(Normy!$G$5*5*Parametry!$B$6/(Parametry!$B$4*(1-Parametry!$B$5)),1)) | D8: =IF(Normy!$G$5="","",ROUND(Normy!$G$5*5*Parametry!$B$6/(Parametry!$B$4*(1-Parametry!$B$5)),1)) | E8: =IF(Normy!$G$5="","",ROUND(Normy!$G$5*5*Parametry!$B$6/(Parametry!$B$4*(1-Parametry!$B$5)),1)) | F8: =IF(Normy!$G$5="","",ROUND(Normy!$G$5*5*Parametry!$B$6/(Parametry!$B$4*(1-Parametry!$B$5)),1)) | G8: =IF(Normy!$G$5="","",ROUND(Normy!$G$5*5*Parametry!$B$6/(Parametry!$B$4*(1-Parametry!$B$5)),1)) | H8: =IF(Normy!$G$5="","",ROUND(Normy!$G$5*5*Parametry!$B$6/(Parametry!$B$4*(1-Parametry!$B$5)),1)) | I8: =IF(Normy!$G$5="","",ROUND(Normy!$G$5*5*Parametry!$B$6/(Parametry!$B$4*(1-Parametry!$B$5)),1)) | J8: =IF(Normy!$G$5="","",ROUND(Normy!$G$5*5*Parametry!$B$6/(Parametry!$B$4*(1-Parametry!$B$5)),1)) | ... BM8: =IF(Normy!$G$5="","",ROUND(Normy!$G$5*5*Parametry!$B$6/(Parametry!$B$4*(1-Parametry!$B$5)),1))
B9: Gap FTE (skut. − potřeba) | C9: =IF(OR(C8="",C7=""),"",C8-C7) | D9: =IF(OR(D8="",D7=""),"",D8-D7) | E9: =IF(OR(E8="",E7=""),"",E8-E7) | F9: =IF(OR(F8="",F7=""),"",F8-F7) | G9: =IF(OR(G8="",G7=""),"",G8-G7) | H9: =IF(OR(H8="",H7=""),"",H8-H7) | I9: =IF(OR(I8="",I7=""),"",I8-I7) | J9: =IF(OR(J8="",J7=""),"",J8-J7) | ... BM9: =IF(OR(BM8="",BM7=""),"",BM8-BM7)
A10: G463 Assembly | B10: Potřebné směny (8h) | C10: =IF(OR(Normy!$C$6="",'Volume po lince'!B5=0),"",ROUNDUP('Volume po lince'!B5/(Normy!$C$6*IF(Normy!$D$6="",Parametry!$B$7,Normy!$D$6)),0)) | D10: =IF(OR(Normy!$C$6="",'Volume po lince'!C5=0),"",ROUNDUP('Volume po lince'!C5/(Normy!$C$6*IF(Normy!$D$6="",Parametry!$B$7,Normy!$D$6)),0)) | E10: =IF(OR(Normy!$C$6="",'Volume po lince'!D5=0),"",ROUNDUP('Volume po lince'!D5/(Normy!$C$6*IF(Normy!$D$6="",Parametry!$B$7,Normy!$D$6)),0)) | F10: =IF(OR(Normy!$C$6="",'Volume po lince'!E5=0),"",ROUNDUP('Volume po lince'!E5/(Normy!$C$6*IF(Normy!$D$6="",Parametry!$B$7,Normy!$D$6)),0)) | G10: =IF(OR(Normy!$C$6="",'Volume po lince'!F5=0),"",ROUNDUP('Volume po lince'!F5/(Normy!$C$6*IF(Normy!$D$6="",Parametry!$B$7,Normy!$D$6)),0)) | H10: =IF(OR(Normy!$C$6="",'Volume po lince'!G5=0),"",ROUNDUP('Volume po lince'!G5/(Normy!$C$6*IF(Normy!$D$6="",Parametry!$B$7,Normy!$D$6)),0)) | I10: =IF(OR(Normy!$C$6="",'Volume po lince'!H5=0),"",ROUNDUP('Volume po lince'!H5/(Normy!$C$6*IF(Normy!$D$6="",Parametry!$B$7,Normy!$D$6)),0)) | J10: =IF(OR(Normy!$C$6="",'Volume po lince'!I5=0),"",ROUNDUP('Volume po lince'!I5/(Normy!$C$6*IF(Normy!$D$6="",Parametry!$B$7,Normy!$D$6)),0)) | ... BM10: =IF(OR(Normy!$C$6="",'Volume po lince'!BL5=0),"",ROUNDUP('Volume po lince'!BL5/(Normy!$C$6*IF(Normy!$D$6="",Parametry!$B$7,Normy!$D$6)),0))
B11: OP-směn | C11: =IF(OR(C10="",Normy!$E$6=""),"",C10*Normy!$E$6) | D11: =IF(OR(D10="",Normy!$E$6=""),"",D10*Normy!$E$6) | E11: =IF(OR(E10="",Normy!$E$6=""),"",E10*Normy!$E$6) | F11: =IF(OR(F10="",Normy!$E$6=""),"",F10*Normy!$E$6) | G11: =IF(OR(G10="",Normy!$E$6=""),"",G10*Normy!$E$6) | H11: =IF(OR(H10="",Normy!$E$6=""),"",H10*Normy!$E$6) | I11: =IF(OR(I10="",Normy!$E$6=""),"",I10*Normy!$E$6) | J11: =IF(OR(J10="",Normy!$E$6=""),"",J10*Normy!$E$6) | ... BM11: =IF(OR(BM10="",Normy!$E$6=""),"",BM10*Normy!$E$6)
B12: Potřeba FTE DL | C12: =IF(C11="","",ROUND(C11*Parametry!$B$6/(Parametry!$B$4*(1-Parametry!$B$5)),1)) | D12: =IF(D11="","",ROUND(D11*Parametry!$B$6/(Parametry!$B$4*(1-Parametry!$B$5)),1)) | E12: =IF(E11="","",ROUND(E11*Parametry!$B$6/(Parametry!$B$4*(1-Parametry!$B$5)),1)) | F12: =IF(F11="","",ROUND(F11*Parametry!$B$6/(Parametry!$B$4*(1-Parametry!$B$5)),1)) | G12: =IF(G11="","",ROUND(G11*Parametry!$B$6/(Parametry!$B$4*(1-Parametry!$B$5)),1)) | H12: =IF(H11="","",ROUND(H11*Parametry!$B$6/(Parametry!$B$4*(1-Parametry!$B$5)),1)) | I12: =IF(I11="","",ROUND(I11*Parametry!$B$6/(Parametry!$B$4*(1-Parametry!$B$5)),1)) | J12: =IF(J11="","",ROUND(J11*Parametry!$B$6/(Parametry!$B$4*(1-Parametry!$B$5)),1)) | ... BM12: =IF(BM11="","",ROUND(BM11*Parametry!$B$6/(Parametry!$B$4*(1-Parametry!$B$5)),1))
B13: Skutečnost FTE | C13: =IF(Normy!$G$6="","",ROUND(Normy!$G$6*5*Parametry!$B$6/(Parametry!$B$4*(1-Parametry!$B$5)),1)) | D13: =IF(Normy!$G$6="","",ROUND(Normy!$G$6*5*Parametry!$B$6/(Parametry!$B$4*(1-Parametry!$B$5)),1)) | E13: =IF(Normy!$G$6="","",ROUND(Normy!$G$6*5*Parametry!$B$6/(Parametry!$B$4*(1-Parametry!$B$5)),1)) | F13: =IF(Normy!$G$6="","",ROUND(Normy!$G$6*5*Parametry!$B$6/(Parametry!$B$4*(1-Parametry!$B$5)),1)) | G13: =IF(Normy!$G$6="","",ROUND(Normy!$G$6*5*Parametry!$B$6/(Parametry!$B$4*(1-Parametry!$B$5)),1)) | H13: =IF(Normy!$G$6="","",ROUND(Normy!$G$6*5*Parametry!$B$6/(Parametry!$B$4*(1-Parametry!$B$5)),1)) | I13: =IF(Normy!$G$6="","",ROUND(Normy!$G$6*5*Parametry!$B$6/(Parametry!$B$4*(1-Parametry!$B$5)),1)) | J13: =IF(Normy!$G$6="","",ROUND(Normy!$G$6*5*Parametry!$B$6/(Parametry!$B$4*(1-Parametry!$B$5)),1)) | ... BM13: =IF(Normy!$G$6="","",ROUND(Normy!$G$6*5*Parametry!$B$6/(Parametry!$B$4*(1-Parametry!$B$5)),1))
B14: Gap FTE (skut. − potřeba) | C14: =IF(OR(C13="",C12=""),"",C13-C12) | D14: =IF(OR(D13="",D12=""),"",D13-D12) | E14: =IF(OR(E13="",E12=""),"",E13-E12) | F14: =IF(OR(F13="",F12=""),"",F13-F12) | G14: =IF(OR(G13="",G12=""),"",G13-G12) | H14: =IF(OR(H13="",H12=""),"",H13-H12) | I14: =IF(OR(I13="",I12=""),"",I13-I12) | J14: =IF(OR(J13="",J12=""),"",J13-J12) | ... BM14: =IF(OR(BM13="",BM12=""),"",BM13-BM12)
A15: IMM | B15: Potřebné směny (8h) | C15: =IF(OR(Normy!$C$7="",'Volume po lince'!B6=0),"",ROUNDUP('Volume po lince'!B6/(Normy!$C$7*IF(Normy!$D$7="",Parametry!$B$7,Normy!$D$7)),0)) | D15: =IF(OR(Normy!$C$7="",'Volume po lince'!C6=0),"",ROUNDUP('Volume po lince'!C6/(Normy!$C$7*IF(Normy!$D$7="",Parametry!$B$7,Normy!$D$7)),0)) | E15: =IF(OR(Normy!$C$7="",'Volume po lince'!D6=0),"",ROUNDUP('Volume po lince'!D6/(Normy!$C$7*IF(Normy!$D$7="",Parametry!$B$7,Normy!$D$7)),0)) | F15: =IF(OR(Normy!$C$7="",'Volume po lince'!E6=0),"",ROUNDUP('Volume po lince'!E6/(Normy!$C$7*IF(Normy!$D$7="",Parametry!$B$7,Normy!$D$7)),0)) | G15: =IF(OR(Normy!$C$7="",'Volume po lince'!F6=0),"",ROUNDUP('Volume po lince'!F6/(Normy!$C$7*IF(Normy!$D$7="",Parametry!$B$7,Normy!$D$7)),0)) | H15: =IF(OR(Normy!$C$7="",'Volume po lince'!G6=0),"",ROUNDUP('Volume po lince'!G6/(Normy!$C$7*IF(Normy!$D$7="",Parametry!$B$7,Normy!$D$7)),0)) | I15: =IF(OR(Normy!$C$7="",'Volume po lince'!H6=0),"",ROUNDUP('Volume po lince'!H6/(Normy!$C$7*IF(Normy!$D$7="",Parametry!$B$7,Normy!$D$7)),0)) | J15: =IF(OR(Normy!$C$7="",'Volume po lince'!I6=0),"",ROUNDUP('Volume po lince'!I6/(Normy!$C$7*IF(Normy!$D$7="",Parametry!$B$7,Normy!$D$7)),0)) | ... BM15: =IF(OR(Normy!$C$7="",'Volume po lince'!BL6=0),"",ROUNDUP('Volume po lince'!BL6/(Normy!$C$7*IF(Normy!$D$7="",Parametry!$B$7,Normy!$D$7)),0))
B16: OP-směn | C16: =IF(OR(C15="",Normy!$E$7=""),"",C15*Normy!$E$7) | D16: =IF(OR(D15="",Normy!$E$7=""),"",D15*Normy!$E$7) | E16: =IF(OR(E15="",Normy!$E$7=""),"",E15*Normy!$E$7) | F16: =IF(OR(F15="",Normy!$E$7=""),"",F15*Normy!$E$7) | G16: =IF(OR(G15="",Normy!$E$7=""),"",G15*Normy!$E$7) | H16: =IF(OR(H15="",Normy!$E$7=""),"",H15*Normy!$E$7) | I16: =IF(OR(I15="",Normy!$E$7=""),"",I15*Normy!$E$7) | J16: =IF(OR(J15="",Normy!$E$7=""),"",J15*Normy!$E$7) | ... BM16: =IF(OR(BM15="",Normy!$E$7=""),"",BM15*Normy!$E$7)
B17: Potřeba FTE DL | C17: =IF(C16="","",ROUND(C16*Parametry!$B$6/(Parametry!$B$4*(1-Parametry!$B$5)),1)) | D17: =IF(D16="","",ROUND(D16*Parametry!$B$6/(Parametry!$B$4*(1-Parametry!$B$5)),1)) | E17: =IF(E16="","",ROUND(E16*Parametry!$B$6/(Parametry!$B$4*(1-Parametry!$B$5)),1)) | F17: =IF(F16="","",ROUND(F16*Parametry!$B$6/(Parametry!$B$4*(1-Parametry!$B$5)),1)) | G17: =IF(G16="","",ROUND(G16*Parametry!$B$6/(Parametry!$B$4*(1-Parametry!$B$5)),1)) | H17: =IF(H16="","",ROUND(H16*Parametry!$B$6/(Parametry!$B$4*(1-Parametry!$B$5)),1)) | I17: =IF(I16="","",ROUND(I16*Parametry!$B$6/(Parametry!$B$4*(1-Parametry!$B$5)),1)) | J17: =IF(J16="","",ROUND(J16*Parametry!$B$6/(Parametry!$B$4*(1-Parametry!$B$5)),1)) | ... BM17: =IF(BM16="","",ROUND(BM16*Parametry!$B$6/(Parametry!$B$4*(1-Parametry!$B$5)),1))
B18: Skutečnost FTE | C18: =IF(Normy!$G$7="","",ROUND(Normy!$G$7*5*Parametry!$B$6/(Parametry!$B$4*(1-Parametry!$B$5)),1)) | D18: =IF(Normy!$G$7="","",ROUND(Normy!$G$7*5*Parametry!$B$6/(Parametry!$B$4*(1-Parametry!$B$5)),1)) | E18: =IF(Normy!$G$7="","",ROUND(Normy!$G$7*5*Parametry!$B$6/(Parametry!$B$4*(1-Parametry!$B$5)),1)) | F18: =IF(Normy!$G$7="","",ROUND(Normy!$G$7*5*Parametry!$B$6/(Parametry!$B$4*(1-Parametry!$B$5)),1)) | G18: =IF(Normy!$G$7="","",ROUND(Normy!$G$7*5*Parametry!$B$6/(Parametry!$B$4*(1-Parametry!$B$5)),1)) | H18: =IF(Normy!$G$7="","",ROUND(Normy!$G$7*5*Parametry!$B$6/(Parametry!$B$4*(1-Parametry!$B$5)),1)) | I18: =IF(Normy!$G$7="","",ROUND(Normy!$G$7*5*Parametry!$B$6/(Parametry!$B$4*(1-Parametry!$B$5)),1)) | J18: =IF(Normy!$G$7="","",ROUND(Normy!$G$7*5*Parametry!$B$6/(Parametry!$B$4*(1-Parametry!$B$5)),1)) | ... BM18: =IF(Normy!$G$7="","",ROUND(Normy!$G$7*5*Parametry!$B$6/(Parametry!$B$4*(1-Parametry!$B$5)),1))
B19: Gap FTE (skut. − potřeba) | C19: =IF(OR(C18="",C17=""),"",C18-C17) | D19: =IF(OR(D18="",D17=""),"",D18-D17) | E19: =IF(OR(E18="",E17=""),"",E18-E17) | F19: =IF(OR(F18="",F17=""),"",F18-F17) | G19: =IF(OR(G18="",G17=""),"",G18-G17) | H19: =IF(OR(H18="",H17=""),"",H18-H17) | I19: =IF(OR(I18="",I17=""),"",I18-I17) | J19: =IF(OR(J18="",J17=""),"",J18-J17) | ... BM19: =IF(OR(BM18="",BM17=""),"",BM18-BM17)
A20: OV51/64 | B20: Potřebné směny (8h) | C20: =IF(OR(Normy!$C$8="",'Volume po lince'!B7=0),"",ROUNDUP('Volume po lince'!B7/(Normy!$C$8*IF(Normy!$D$8="",Parametry!$B$7,Normy!$D$8)),0)) | D20: =IF(OR(Normy!$C$8="",'Volume po lince'!C7=0),"",ROUNDUP('Volume po lince'!C7/(Normy!$C$8*IF(Normy!$D$8="",Parametry!$B$7,Normy!$D$8)),0)) | E20: =IF(OR(Normy!$C$8="",'Volume po lince'!D7=0),"",ROUNDUP('Volume po lince'!D7/(Normy!$C$8*IF(Normy!$D$8="",Parametry!$B$7,Normy!$D$8)),0)) | F20: =IF(OR(Normy!$C$8="",'Volume po lince'!E7=0),"",ROUNDUP('Volume po lince'!E7/(Normy!$C$8*IF(Normy!$D$8="",Parametry!$B$7,Normy!$D$8)),0)) | G20: =IF(OR(Normy!$C$8="",'Volume po lince'!F7=0),"",ROUNDUP('Volume po lince'!F7/(Normy!$C$8*IF(Normy!$D$8="",Parametry!$B$7,Normy!$D$8)),0)) | H20: =IF(OR(Normy!$C$8="",'Volume po lince'!G7=0),"",ROUNDUP('Volume po lince'!G7/(Normy!$C$8*IF(Normy!$D$8="",Parametry!$B$7,Normy!$D$8)),0)) | I20: =IF(OR(Normy!$C$8="",'Volume po lince'!H7=0),"",ROUNDUP('Volume po lince'!H7/(Normy!$C$8*IF(Normy!$D$8="",Parametry!$B$7,Normy!$D$8)),0)) | J20: =IF(OR(Normy!$C$8="",'Volume po lince'!I7=0),"",ROUNDUP('Volume po lince'!I7/(Normy!$C$8*IF(Normy!$D$8="",Parametry!$B$7,Normy!$D$8)),0)) | ... BM20: =IF(OR(Normy!$C$8="",'Volume po lince'!BL7=0),"",ROUNDUP('Volume po lince'!BL7/(Normy!$C$8*IF(Normy!$D$8="",Parametry!$B$7,Normy!$D$8)),0))
B21: OP-směn | C21: =IF(OR(C20="",Normy!$E$8=""),"",C20*Normy!$E$8) | D21: =IF(OR(D20="",Normy!$E$8=""),"",D20*Normy!$E$8) | E21: =IF(OR(E20="",Normy!$E$8=""),"",E20*Normy!$E$8) | F21: =IF(OR(F20="",Normy!$E$8=""),"",F20*Normy!$E$8) | G21: =IF(OR(G20="",Normy!$E$8=""),"",G20*Normy!$E$8) | H21: =IF(OR(H20="",Normy!$E$8=""),"",H20*Normy!$E$8) | I21: =IF(OR(I20="",Normy!$E$8=""),"",I20*Normy!$E$8) | J21: =IF(OR(J20="",Normy!$E$8=""),"",J20*Normy!$E$8) | ... BM21: =IF(OR(BM20="",Normy!$E$8=""),"",BM20*Normy!$E$8)
B22: Potřeba FTE DL | C22: =IF(C21="","",ROUND(C21*Parametry!$B$6/(Parametry!$B$4*(1-Parametry!$B$5)),1)) | D22: =IF(D21="","",ROUND(D21*Parametry!$B$6/(Parametry!$B$4*(1-Parametry!$B$5)),1)) | E22: =IF(E21="","",ROUND(E21*Parametry!$B$6/(Parametry!$B$4*(1-Parametry!$B$5)),1)) | F22: =IF(F21="","",ROUND(F21*Parametry!$B$6/(Parametry!$B$4*(1-Parametry!$B$5)),1)) | G22: =IF(G21="","",ROUND(G21*Parametry!$B$6/(Parametry!$B$4*(1-Parametry!$B$5)),1)) | H22: =IF(H21="","",ROUND(H21*Parametry!$B$6/(Parametry!$B$4*(1-Parametry!$B$5)),1)) | I22: =IF(I21="","",ROUND(I21*Parametry!$B$6/(Parametry!$B$4*(1-Parametry!$B$5)),1)) | J22: =IF(J21="","",ROUND(J21*Parametry!$B$6/(Parametry!$B$4*(1-Parametry!$B$5)),1)) | ... BM22: =IF(BM21="","",ROUND(BM21*Parametry!$B$6/(Parametry!$B$4*(1-Parametry!$B$5)),1))
B23: Skutečnost FTE | C23: =IF(Normy!$G$8="","",ROUND(Normy!$G$8*5*Parametry!$B$6/(Parametry!$B$4*(1-Parametry!$B$5)),1)) | D23: =IF(Normy!$G$8="","",ROUND(Normy!$G$8*5*Parametry!$B$6/(Parametry!$B$4*(1-Parametry!$B$5)),1)) | E23: =IF(Normy!$G$8="","",ROUND(Normy!$G$8*5*Parametry!$B$6/(Parametry!$B$4*(1-Parametry!$B$5)),1)) | F23: =IF(Normy!$G$8="","",ROUND(Normy!$G$8*5*Parametry!$B$6/(Parametry!$B$4*(1-Parametry!$B$5)),1)) | G23: =IF(Normy!$G$8="","",ROUND(Normy!$G$8*5*Parametry!$B$6/(Parametry!$B$4*(1-Parametry!$B$5)),1)) | H23: =IF(Normy!$G$8="","",ROUND(Normy!$G$8*5*Parametry!$B$6/(Parametry!$B$4*(1-Parametry!$B$5)),1)) | I23: =IF(Normy!$G$8="","",ROUND(Normy!$G$8*5*Parametry!$B$6/(Parametry!$B$4*(1-Parametry!$B$5)),1)) | J23: =IF(Normy!$G$8="","",ROUND(Normy!$G$8*5*Parametry!$B$6/(Parametry!$B$4*(1-Parametry!$B$5)),1)) | ... BM23: =IF(Normy!$G$8="","",ROUND(Normy!$G$8*5*Parametry!$B$6/(Parametry!$B$4*(1-Parametry!$B$5)),1))
B24: Gap FTE (skut. − potřeba) | C24: =IF(OR(C23="",C22=""),"",C23-C22) | D24: =IF(OR(D23="",D22=""),"",D23-D22) | E24: =IF(OR(E23="",E22=""),"",E23-E22) | F24: =IF(OR(F23="",F22=""),"",F23-F22) | G24: =IF(OR(G23="",G22=""),"",G23-G22) | H24: =IF(OR(H23="",H22=""),"",H23-H22) | I24: =IF(OR(I23="",I22=""),"",I23-I22) | J24: =IF(OR(J23="",J22=""),"",J23-J22) | ... BM24: =IF(OR(BM23="",BM22=""),"",BM23-BM22)
A25: GB/DP | B25: Potřebné směny (8h) | C25: =IF(OR(Normy!$C$9="",'Volume po lince'!B8=0),"",ROUNDUP('Volume po lince'!B8/(Normy!$C$9*IF(Normy!$D$9="",Parametry!$B$7,Normy!$D$9)),0)) | D25: =IF(OR(Normy!$C$9="",'Volume po lince'!C8=0),"",ROUNDUP('Volume po lince'!C8/(Normy!$C$9*IF(Normy!$D$9="",Parametry!$B$7,Normy!$D$9)),0)) | E25: =IF(OR(Normy!$C$9="",'Volume po lince'!D8=0),"",ROUNDUP('Volume po lince'!D8/(Normy!$C$9*IF(Normy!$D$9="",Parametry!$B$7,Normy!$D$9)),0)) | F25: =IF(OR(Normy!$C$9="",'Volume po lince'!E8=0),"",ROUNDUP('Volume po lince'!E8/(Normy!$C$9*IF(Normy!$D$9="",Parametry!$B$7,Normy!$D$9)),0)) | G25: =IF(OR(Normy!$C$9="",'Volume po lince'!F8=0),"",ROUNDUP('Volume po lince'!F8/(Normy!$C$9*IF(Normy!$D$9="",Parametry!$B$7,Normy!$D$9)),0)) | H25: =IF(OR(Normy!$C$9="",'Volume po lince'!G8=0),"",ROUNDUP('Volume po lince'!G8/(Normy!$C$9*IF(Normy!$D$9="",Parametry!$B$7,Normy!$D$9)),0)) | I25: =IF(OR(Normy!$C$9="",'Volume po lince'!H8=0),"",ROUNDUP('Volume po lince'!H8/(Normy!$C$9*IF(Normy!$D$9="",Parametry!$B$7,Normy!$D$9)),0)) | J25: =IF(OR(Normy!$C$9="",'Volume po lince'!I8=0),"",ROUNDUP('Volume po lince'!I8/(Normy!$C$9*IF(Normy!$D$9="",Parametry!$B$7,Normy!$D$9)),0)) | ... BM25: =IF(OR(Normy!$C$9="",'Volume po lince'!BL8=0),"",ROUNDUP('Volume po lince'!BL8/(Normy!$C$9*IF(Normy!$D$9="",Parametry!$B$7,Normy!$D$9)),0))
B26: OP-směn | C26: =IF(OR(C25="",Normy!$E$9=""),"",C25*Normy!$E$9) | D26: =IF(OR(D25="",Normy!$E$9=""),"",D25*Normy!$E$9) | E26: =IF(OR(E25="",Normy!$E$9=""),"",E25*Normy!$E$9) | F26: =IF(OR(F25="",Normy!$E$9=""),"",F25*Normy!$E$9) | G26: =IF(OR(G25="",Normy!$E$9=""),"",G25*Normy!$E$9) | H26: =IF(OR(H25="",Normy!$E$9=""),"",H25*Normy!$E$9) | I26: =IF(OR(I25="",Normy!$E$9=""),"",I25*Normy!$E$9) | J26: =IF(OR(J25="",Normy!$E$9=""),"",J25*Normy!$E$9) | ... BM26: =IF(OR(BM25="",Normy!$E$9=""),"",BM25*Normy!$E$9)
B27: Potřeba FTE DL | C27: =IF(C26="","",ROUND(C26*Parametry!$B$6/(Parametry!$B$4*(1-Parametry!$B$5)),1)) | D27: =IF(D26="","",ROUND(D26*Parametry!$B$6/(Parametry!$B$4*(1-Parametry!$B$5)),1)) | E27: =IF(E26="","",ROUND(E26*Parametry!$B$6/(Parametry!$B$4*(1-Parametry!$B$5)),1)) | F27: =IF(F26="","",ROUND(F26*Parametry!$B$6/(Parametry!$B$4*(1-Parametry!$B$5)),1)) | G27: =IF(G26="","",ROUND(G26*Parametry!$B$6/(Parametry!$B$4*(1-Parametry!$B$5)),1)) | H27: =IF(H26="","",ROUND(H26*Parametry!$B$6/(Parametry!$B$4*(1-Parametry!$B$5)),1)) | I27: =IF(I26="","",ROUND(I26*Parametry!$B$6/(Parametry!$B$4*(1-Parametry!$B$5)),1)) | J27: =IF(J26="","",ROUND(J26*Parametry!$B$6/(Parametry!$B$4*(1-Parametry!$B$5)),1)) | ... BM27: =IF(BM26="","",ROUND(BM26*Parametry!$B$6/(Parametry!$B$4*(1-Parametry!$B$5)),1))
B28: Skutečnost FTE | C28: =IF(Normy!$G$9="","",ROUND(Normy!$G$9*5*Parametry!$B$6/(Parametry!$B$4*(1-Parametry!$B$5)),1)) | D28: =IF(Normy!$G$9="","",ROUND(Normy!$G$9*5*Parametry!$B$6/(Parametry!$B$4*(1-Parametry!$B$5)),1)) | E28: =IF(Normy!$G$9="","",ROUND(Normy!$G$9*5*Parametry!$B$6/(Parametry!$B$4*(1-Parametry!$B$5)),1)) | F28: =IF(Normy!$G$9="","",ROUND(Normy!$G$9*5*Parametry!$B$6/(Parametry!$B$4*(1-Parametry!$B$5)),1)) | G28: =IF(Normy!$G$9="","",ROUND(Normy!$G$9*5*Parametry!$B$6/(Parametry!$B$4*(1-Parametry!$B$5)),1)) | H28: =IF(Normy!$G$9="","",ROUND(Normy!$G$9*5*Parametry!$B$6/(Parametry!$B$4*(1-Parametry!$B$5)),1)) | I28: =IF(Normy!$G$9="","",ROUND(Normy!$G$9*5*Parametry!$B$6/(Parametry!$B$4*(1-Parametry!$B$5)),1)) | J28: =IF(Normy!$G$9="","",ROUND(Normy!$G$9*5*Parametry!$B$6/(Parametry!$B$4*(1-Parametry!$B$5)),1)) | ... BM28: =IF(Normy!$G$9="","",ROUND(Normy!$G$9*5*Parametry!$B$6/(Parametry!$B$4*(1-Parametry!$B$5)),1))
B29: Gap FTE (skut. − potřeba) | C29: =IF(OR(C28="",C27=""),"",C28-C27) | D29: =IF(OR(D28="",D27=""),"",D28-D27) | E29: =IF(OR(E28="",E27=""),"",E28-E27) | F29: =IF(OR(F28="",F27=""),"",F28-F27) | G29: =IF(OR(G28="",G27=""),"",G28-G27) | H29: =IF(OR(H28="",H27=""),"",H28-H27) | I29: =IF(OR(I28="",I27=""),"",I28-I27) | J29: =IF(OR(J28="",J27=""),"",J28-J27) | ... BM29: =IF(OR(BM28="",BM27=""),"",BM28-BM27)
A30: SK336/W206 | B30: Potřebné směny (8h) | C30: =IF(OR(Normy!$C$10="",'Volume po lince'!B9=0),"",ROUNDUP('Volume po lince'!B9/(Normy!$C$10*IF(Normy!$D$10="",Parametry!$B$7,Normy!$D$10)),0)) | D30: =IF(OR(Normy!$C$10="",'Volume po lince'!C9=0),"",ROUNDUP('Volume po lince'!C9/(Normy!$C$10*IF(Normy!$D$10="",Parametry!$B$7,Normy!$D$10)),0)) | E30: =IF(OR(Normy!$C$10="",'Volume po lince'!D9=0),"",ROUNDUP('Volume po lince'!D9/(Normy!$C$10*IF(Normy!$D$10="",Parametry!$B$7,Normy!$D$10)),0)) | F30: =IF(OR(Normy!$C$10="",'Volume po lince'!E9=0),"",ROUNDUP('Volume po lince'!E9/(Normy!$C$10*IF(Normy!$D$10="",Parametry!$B$7,Normy!$D$10)),0)) | G30: =IF(OR(Normy!$C$10="",'Volume po lince'!F9=0),"",ROUNDUP('Volume po lince'!F9/(Normy!$C$10*IF(Normy!$D$10="",Parametry!$B$7,Normy!$D$10)),0)) | H30: =IF(OR(Normy!$C$10="",'Volume po lince'!G9=0),"",ROUNDUP('Volume po lince'!G9/(Normy!$C$10*IF(Normy!$D$10="",Parametry!$B$7,Normy!$D$10)),0)) | I30: =IF(OR(Normy!$C$10="",'Volume po lince'!H9=0),"",ROUNDUP('Volume po lince'!H9/(Normy!$C$10*IF(Normy!$D$10="",Parametry!$B$7,Normy!$D$10)),0)) | J30: =IF(OR(Normy!$C$10="",'Volume po lince'!I9=0),"",ROUNDUP('Volume po lince'!I9/(Normy!$C$10*IF(Normy!$D$10="",Parametry!$B$7,Normy!$D$10)),0)) | ... BM30: =IF(OR(Normy!$C$10="",'Volume po lince'!BL9=0),"",ROUNDUP('Volume po lince'!BL9/(Normy!$C$10*IF(Normy!$D$10="",Parametry!$B$7,Normy!$D$10)),0))
B31: OP-směn | C31: =IF(OR(C30="",Normy!$E$10=""),"",C30*Normy!$E$10) | D31: =IF(OR(D30="",Normy!$E$10=""),"",D30*Normy!$E$10) | E31: =IF(OR(E30="",Normy!$E$10=""),"",E30*Normy!$E$10) | F31: =IF(OR(F30="",Normy!$E$10=""),"",F30*Normy!$E$10) | G31: =IF(OR(G30="",Normy!$E$10=""),"",G30*Normy!$E$10) | H31: =IF(OR(H30="",Normy!$E$10=""),"",H30*Normy!$E$10) | I31: =IF(OR(I30="",Normy!$E$10=""),"",I30*Normy!$E$10) | J31: =IF(OR(J30="",Normy!$E$10=""),"",J30*Normy!$E$10) | ... BM31: =IF(OR(BM30="",Normy!$E$10=""),"",BM30*Normy!$E$10)
B32: Potřeba FTE DL | C32: =IF(C31="","",ROUND(C31*Parametry!$B$6/(Parametry!$B$4*(1-Parametry!$B$5)),1)) | D32: =IF(D31="","",ROUND(D31*Parametry!$B$6/(Parametry!$B$4*(1-Parametry!$B$5)),1)) | E32: =IF(E31="","",ROUND(E31*Parametry!$B$6/(Parametry!$B$4*(1-Parametry!$B$5)),1)) | F32: =IF(F31="","",ROUND(F31*Parametry!$B$6/(Parametry!$B$4*(1-Parametry!$B$5)),1)) | G32: =IF(G31="","",ROUND(G31*Parametry!$B$6/(Parametry!$B$4*(1-Parametry!$B$5)),1)) | H32: =IF(H31="","",ROUND(H31*Parametry!$B$6/(Parametry!$B$4*(1-Parametry!$B$5)),1)) | I32: =IF(I31="","",ROUND(I31*Parametry!$B$6/(Parametry!$B$4*(1-Parametry!$B$5)),1)) | J32: =IF(J31="","",ROUND(J31*Parametry!$B$6/(Parametry!$B$4*(1-Parametry!$B$5)),1)) | ... BM32: =IF(BM31="","",ROUND(BM31*Parametry!$B$6/(Parametry!$B$4*(1-Parametry!$B$5)),1))
B33: Skutečnost FTE | C33: =IF(Normy!$G$10="","",ROUND(Normy!$G$10*5*Parametry!$B$6/(Parametry!$B$4*(1-Parametry!$B$5)),1)) | D33: =IF(Normy!$G$10="","",ROUND(Normy!$G$10*5*Parametry!$B$6/(Parametry!$B$4*(1-Parametry!$B$5)),1)) | E33: =IF(Normy!$G$10="","",ROUND(Normy!$G$10*5*Parametry!$B$6/(Parametry!$B$4*(1-Parametry!$B$5)),1)) | F33: =IF(Normy!$G$10="","",ROUND(Normy!$G$10*5*Parametry!$B$6/(Parametry!$B$4*(1-Parametry!$B$5)),1)) | G33: =IF(Normy!$G$10="","",ROUND(Normy!$G$10*5*Parametry!$B$6/(Parametry!$B$4*(1-Parametry!$B$5)),1)) | H33: =IF(Normy!$G$10="","",ROUND(Normy!$G$10*5*Parametry!$B$6/(Parametry!$B$4*(1-Parametry!$B$5)),1)) | I33: =IF(Normy!$G$10="","",ROUND(Normy!$G$10*5*Parametry!$B$6/(Parametry!$B$4*(1-Parametry!$B$5)),1)) | J33: =IF(Normy!$G$10="","",ROUND(Normy!$G$10*5*Parametry!$B$6/(Parametry!$B$4*(1-Parametry!$B$5)),1)) | ... BM33: =IF(Normy!$G$10="","",ROUND(Normy!$G$10*5*Parametry!$B$6/(Parametry!$B$4*(1-Parametry!$B$5)),1))
B34: Gap FTE (skut. − potřeba) | C34: =IF(OR(C33="",C32=""),"",C33-C32) | D34: =IF(OR(D33="",D32=""),"",D33-D32) | E34: =IF(OR(E33="",E32=""),"",E33-E32) | F34: =IF(OR(F33="",F32=""),"",F33-F32) | G34: =IF(OR(G33="",G32=""),"",G33-G32) | H34: =IF(OR(H33="",H32=""),"",H33-H32) | I34: =IF(OR(I33="",I32=""),"",I33-I32) | J34: =IF(OR(J33="",J32=""),"",J33-J32) | ... BM34: =IF(OR(BM33="",BM32=""),"",BM33-BM32)
A35: MBEAM | B35: Potřebné směny (8h) | C35: =IF(OR(Normy!$C$11="",'Volume po lince'!B10=0),"",ROUNDUP('Volume po lince'!B10/(Normy!$C$11*IF(Normy!$D$11="",Parametry!$B$7,Normy!$D$11)),0)) | D35: =IF(OR(Normy!$C$11="",'Volume po lince'!C10=0),"",ROUNDUP('Volume po lince'!C10/(Normy!$C$11*IF(Normy!$D$11="",Parametry!$B$7,Normy!$D$11)),0)) | E35: =IF(OR(Normy!$C$11="",'Volume po lince'!D10=0),"",ROUNDUP('Volume po lince'!D10/(Normy!$C$11*IF(Normy!$D$11="",Parametry!$B$7,Normy!$D$11)),0)) | F35: =IF(OR(Normy!$C$11="",'Volume po lince'!E10=0),"",ROUNDUP('Volume po lince'!E10/(Normy!$C$11*IF(Normy!$D$11="",Parametry!$B$7,Normy!$D$11)),0)) | G35: =IF(OR(Normy!$C$11="",'Volume po lince'!F10=0),"",ROUNDUP('Volume po lince'!F10/(Normy!$C$11*IF(Normy!$D$11="",Parametry!$B$7,Normy!$D$11)),0)) | H35: =IF(OR(Normy!$C$11="",'Volume po lince'!G10=0),"",ROUNDUP('Volume po lince'!G10/(Normy!$C$11*IF(Normy!$D$11="",Parametry!$B$7,Normy!$D$11)),0)) | I35: =IF(OR(Normy!$C$11="",'Volume po lince'!H10=0),"",ROUNDUP('Volume po lince'!H10/(Normy!$C$11*IF(Normy!$D$11="",Parametry!$B$7,Normy!$D$11)),0)) | J35: =IF(OR(Normy!$C$11="",'Volume po lince'!I10=0),"",ROUNDUP('Volume po lince'!I10/(Normy!$C$11*IF(Normy!$D$11="",Parametry!$B$7,Normy!$D$11)),0)) | ... BM35: =IF(OR(Normy!$C$11="",'Volume po lince'!BL10=0),"",ROUNDUP('Volume po lince'!BL10/(Normy!$C$11*IF(Normy!$D$11="",Parametry!$B$7,Normy!$D$11)),0))
B36: OP-směn | C36: =IF(OR(C35="",Normy!$E$11=""),"",C35*Normy!$E$11) | D36: =IF(OR(D35="",Normy!$E$11=""),"",D35*Normy!$E$11) | E36: =IF(OR(E35="",Normy!$E$11=""),"",E35*Normy!$E$11) | F36: =IF(OR(F35="",Normy!$E$11=""),"",F35*Normy!$E$11) | G36: =IF(OR(G35="",Normy!$E$11=""),"",G35*Normy!$E$11) | H36: =IF(OR(H35="",Normy!$E$11=""),"",H35*Normy!$E$11) | I36: =IF(OR(I35="",Normy!$E$11=""),"",I35*Normy!$E$11) | J36: =IF(OR(J35="",Normy!$E$11=""),"",J35*Normy!$E$11) | ... BM36: =IF(OR(BM35="",Normy!$E$11=""),"",BM35*Normy!$E$11)
B37: Potřeba FTE DL | C37: =IF(C36="","",ROUND(C36*Parametry!$B$6/(Parametry!$B$4*(1-Parametry!$B$5)),1)) | D37: =IF(D36="","",ROUND(D36*Parametry!$B$6/(Parametry!$B$4*(1-Parametry!$B$5)),1)) | E37: =IF(E36="","",ROUND(E36*Parametry!$B$6/(Parametry!$B$4*(1-Parametry!$B$5)),1)) | F37: =IF(F36="","",ROUND(F36*Parametry!$B$6/(Parametry!$B$4*(1-Parametry!$B$5)),1)) | G37: =IF(G36="","",ROUND(G36*Parametry!$B$6/(Parametry!$B$4*(1-Parametry!$B$5)),1)) | H37: =IF(H36="","",ROUND(H36*Parametry!$B$6/(Parametry!$B$4*(1-Parametry!$B$5)),1)) | I37: =IF(I36="","",ROUND(I36*Parametry!$B$6/(Parametry!$B$4*(1-Parametry!$B$5)),1)) | J37: =IF(J36="","",ROUND(J36*Parametry!$B$6/(Parametry!$B$4*(1-Parametry!$B$5)),1)) | ... BM37: =IF(BM36="","",ROUND(BM36*Parametry!$B$6/(Parametry!$B$4*(1-Parametry!$B$5)),1))
B38: Skutečnost FTE | C38: =IF(Normy!$G$11="","",ROUND(Normy!$G$11*5*Parametry!$B$6/(Parametry!$B$4*(1-Parametry!$B$5)),1)) | D38: =IF(Normy!$G$11="","",ROUND(Normy!$G$11*5*Parametry!$B$6/(Parametry!$B$4*(1-Parametry!$B$5)),1)) | E38: =IF(Normy!$G$11="","",ROUND(Normy!$G$11*5*Parametry!$B$6/(Parametry!$B$4*(1-Parametry!$B$5)),1)) | F38: =IF(Normy!$G$11="","",ROUND(Normy!$G$11*5*Parametry!$B$6/(Parametry!$B$4*(1-Parametry!$B$5)),1)) | G38: =IF(Normy!$G$11="","",ROUND(Normy!$G$11*5*Parametry!$B$6/(Parametry!$B$4*(1-Parametry!$B$5)),1)) | H38: =IF(Normy!$G$11="","",ROUND(Normy!$G$11*5*Parametry!$B$6/(Parametry!$B$4*(1-Parametry!$B$5)),1)) | I38: =IF(Normy!$G$11="","",ROUND(Normy!$G$11*5*Parametry!$B$6/(Parametry!$B$4*(1-Parametry!$B$5)),1)) | J38: =IF(Normy!$G$11="","",ROUND(Normy!$G$11*5*Parametry!$B$6/(Parametry!$B$4*(1-Parametry!$B$5)),1)) | ... BM38: =IF(Normy!$G$11="","",ROUND(Normy!$G$11*5*Parametry!$B$6/(Parametry!$B$4*(1-Parametry!$B$5)),1))
B39: Gap FTE (skut. − potřeba) | C39: =IF(OR(C38="",C37=""),"",C38-C37) | D39: =IF(OR(D38="",D37=""),"",D38-D37) | E39: =IF(OR(E38="",E37=""),"",E38-E37) | F39: =IF(OR(F38="",F37=""),"",F38-F37) | G39: =IF(OR(G38="",G37=""),"",G38-G37) | H39: =IF(OR(H38="",H37=""),"",H38-H37) | I39: =IF(OR(I38="",I37=""),"",I38-I37) | J39: =IF(OR(J38="",J37=""),"",J38-J37) | ... BM39: =IF(OR(BM38="",BM37=""),"",BM38-BM37)
A40: W177/W247 IP | B40: Potřebné směny (8h) | C40: =IF(OR(Normy!$C$12="",'Volume po lince'!B11=0),"",ROUNDUP('Volume po lince'!B11/(Normy!$C$12*IF(Normy!$D$12="",Parametry!$B$7,Normy!$D$12)),0)) | D40: =IF(OR(Normy!$C$12="",'Volume po lince'!C11=0),"",ROUNDUP('Volume po lince'!C11/(Normy!$C$12*IF(Normy!$D$12="",Parametry!$B$7,Normy!$D$12)),0)) | E40: =IF(OR(Normy!$C$12="",'Volume po lince'!D11=0),"",ROUNDUP('Volume po lince'!D11/(Normy!$C$12*IF(Normy!$D$12="",Parametry!$B$7,Normy!$D$12)),0)) | F40: =IF(OR(Normy!$C$12="",'Volume po lince'!E11=0),"",ROUNDUP('Volume po lince'!E11/(Normy!$C$12*IF(Normy!$D$12="",Parametry!$B$7,Normy!$D$12)),0)) | G40: =IF(OR(Normy!$C$12="",'Volume po lince'!F11=0),"",ROUNDUP('Volume po lince'!F11/(Normy!$C$12*IF(Normy!$D$12="",Parametry!$B$7,Normy!$D$12)),0)) | H40: =IF(OR(Normy!$C$12="",'Volume po lince'!G11=0),"",ROUNDUP('Volume po lince'!G11/(Normy!$C$12*IF(Normy!$D$12="",Parametry!$B$7,Normy!$D$12)),0)) | I40: =IF(OR(Normy!$C$12="",'Volume po lince'!H11=0),"",ROUNDUP('Volume po lince'!H11/(Normy!$C$12*IF(Normy!$D$12="",Parametry!$B$7,Normy!$D$12)),0)) | J40: =IF(OR(Normy!$C$12="",'Volume po lince'!I11=0),"",ROUNDUP('Volume po lince'!I11/(Normy!$C$12*IF(Normy!$D$12="",Parametry!$B$7,Normy!$D$12)),0)) | ... BM40: =IF(OR(Normy!$C$12="",'Volume po lince'!BL11=0),"",ROUNDUP('Volume po lince'!BL11/(Normy!$C$12*IF(Normy!$D$12="",Parametry!$B$7,Normy!$D$12)),0))
...

Sheet Linky z rozpisů
A1: Obsazení linek podle rozpisů směn CW43/2026
A2: Počet jmenovitě obsazených operátorů na směně (bez TL/TR). 12h = z toho lidé na 12h směně (06–18 / 18–06), kryjí i část odpolední.
A4: Rozpis (skupina) | B4: OP ranní | C4: OP odpolední | D4: OP noční | E4: OP za den (unikátní jména) | F4: z toho 12h | G4: TL/TR za den | H4: Pozice v rozpisu (R/O/N) | I4: Soubor | J4: List | K4: Poznámka | L4: Stejné jméno i v jiném rozpisu
A5: OV51/64 | B5: 14 | C5: 0 | D5: 13 | E5: 27 | F5: 2 | G5: 3 | H5: 14/13/13 | I5: CW43_OV_51_64.xlsx | J5: CW43 | K5: List CW43 je nadepsán CW44. Odpolední: 13 pozic bez jmen. 4 lidé končí 30.10., 2 návraty 1.11. | L5: Biro Kristina, Tsiple Maryna
A6: IMM | B6: 16 | C6: 10 | D6: 15 | E6: 41 | F6: 13 | G6: 6 | H6: 16/10/15 | I6: CW_43_IMM.xlsx | J6: CW43 | K6: Rozpis sám uvádí 17/11/16 (vč. pomoc TL).
A7: SK336/W206 | B7: 9 | C7: 2 | D7: 9 | E7: 20 | F7: 15 | G7: 3 | H7: 9/2/9 | I7: CW_43_SK336.xlsx | J7: CW43 | K7: Odpolední jen Us.Wel + Rework, zbytek kryjí 12h směny. | L7: Tsiple Maryna
A8: Slush | B8: 8 | C8: 2 | D8: 8 | E8: 18 | F8: 12 | G8: 5 | H8: 8/3/8 | I8: CW_43_Slush___it_.xlsx | J8: 43 | K8: Slush 1+2, manipulant, myčka. Sewing a Sealing MFA bez obsazení.
A9: W177/W247 IP (MFA2) | B9: 7 | C9: 0 | D9: 7 | E9: 14 | F9: 14 | G9: 5 | H9: 7/7/7 | I9: CW_43_MFA2.xlsx | J9: CW39 | K9: Soubor obsahuje jen týden 42 (list CW39) – CW43 chybí. | L9: Tsiple Maryna
A10: MBEAM | B10: 10 | C10: 9 | D10: 9 | E10: 28 | F10: 0 | G10: 5 | H10: 10/9/9 | I10: CW_43_Mbeam_.xlsx | J10: cw7 | K10: X540 / W520 / V530. | L10: Biro Kristina
A11: G463 Assembly | B11: 12 | C11: 11 | D11: 9 | E11: 31 | F11: 7 | G11: 4 | H11: 11/11/9 | I11: CW_43_G463_aktual.xlsx | J11: CW 24 2024 | K11: List „CW 24 2024“ = týden 43. Lidé 18–22 / 18–06 počítáni jednou. QS na rework nepočítán. | L11: Virich Oleksandr
A12: GB/DP | B12: 10 | C12: 5 | D12: 0 | E12: 15 | F12: 2 | G12: 1 | H12: 10/5/0 | I12: CW_43GBDP1.xlsx | J12: CW 24 2024 | K12: Bez noční směny.
A13: Foaming K2 | B13: 9 | C13: 7 | D13: 9 | E13: 25 | F13: 3 | G13: 5 (TL+TR, celý Foam) | I13: CW_43_Foam___.xlsx | J13: Vzor | K13: Start neděle 18:00. Pec, sekvence, manipulant, rework, karusel. Odpolední: pozice z části bez jmen.
A14: Foam Scoring | B14: 3 | C14: 0 | D14: 3 | E14: 6 | F14: 0 | G14: 0 | I14: CW_43_Foam___.xlsx | J14: Vzor | K14: Scoring u K2, start 06/14/22. Odpolední: 3 pozice bez jmen.
A15: Foaming K1 | B15: 7 | C15: 0 | D15: 0 | E15: 7 | F15: 7 | G15: 0 | I15: CW_43_Foam___.xlsx | J15: Vzor | K15: Start pondělí 6:00. Jede jen ranní 12h (06–18), 7 OP; odpolední a noční jen pozice bez jmen → K1 jede 1 směnu denně.
A16: G463 Prefix | B16: 24 / 20 | C16: 12 | D16: 24 | E16: 60 | F16: 68 | G16: 2/3/1/3 | I16: Prefix_akrual.xlsx | J16: WEEK17 | K16: Ranní: dvě 12h party A/B (střídají se). OP za den = party A + odpolední + noční. Celkem všech part: 80. Není v převodníku jako samostatný projekt. | L16: Virich Oleksandr

Sheet Kontrola jmen
A1: Rozpis | B1: Směna | C1: Jméno | D1: Pozice | E1: Čas | F1: Soubor | G1: List | H1: Řádek
A2: OV51/64 | B2: R | C2: Macha Michal | D2: Punching | E2: 06:00-14:00 | F2: CW43_OV_51_64.xlsx | G2: CW43 | H2: 15
A3: OV51/64 | B3: N | C3: Rotaras V./Ilhak Y. | D3: Punching | E3: 22:00-06:00 | F3: CW43_OV_51_64.xlsx | G3: CW43 | H3: 15
A4: OV51/64 | B4: R | C4: Synyshyn Vitalii | D4: Milling | E4: 06:00-14:00 | F4: CW43_OV_51_64.xlsx | G4: CW43 | H4: 16
A5: OV51/64 | B5: N | C5: Vakulenko Yurii | D5: Milling | E5: 22:00-06:00 | F5: CW43_OV_51_64.xlsx | G5: CW43 | H5: 16
A6: OV51/64 | B6: R | C6: Volkova Olena | D6: Welding | E6: 06:00-14:00 | F6: CW43_OV_51_64.xlsx | G6: CW43 | H6: 17
A7: OV51/64 | B7: N | C7: Potekhina Ksenia | D7: Welding | E7: 22:00-06:00 | F7: CW43_OV_51_64.xlsx | G7: CW43 | H7: 17
A8: OV51/64 | B8: R | C8: Sačipovič Nataša | D8: Assy Airbag | E8: 06:00-14:00 | F8: CW43_OV_51_64.xlsx | G8: CW43 | H8: 18
A9: OV51/64 | B9: N | C9: Rotaras Aliona | D9: Assy Airbag | E9: 22:00-06:00 | F9: CW43_OV_51_64.xlsx | G9: CW43 | H9: 18
A10: OV51/64 | B10: R | C10: Popova Ludmyla | D10: Klipping | E10: 06:00-14:00 | F10: CW43_OV_51_64.xlsx | G10: CW43 | H10: 19
A11: OV51/64 | B11: N | C11: Kodymskyi/Karpov R | D11: Preassy | E11: 22:00-06:00 | F11: CW43_OV_51_64.xlsx | G11: CW43 | H11: 19
A12: OV51/64 | B12: R | C12: Berchi Catalin | D12: Preassy | E12: 06:00-14:00 | F12: CW43_OV_51_64.xlsx | G12: CW43 | H12: 20
A13: OV51/64 | B13: N | C13: Kupych Volodymyr | D13: Station 1 | E13: 22:00-06:00 | F13: CW43_OV_51_64.xlsx | G13: CW43 | H13: 20
... A35: IMM | B35: N | C35: Shmatko Oleksandr | D35: laser | E35: 22:00-06:00 | F35: CW_43_IMM.xlsx | G35: CW43 | H35: 14
A36: IMM | B36: R | C36: Gurung Nabin | E36: 06:00 - 18:00 | F36: CW_43_IMM.xlsx | G36: CW43 | H36: 15
A37: IMM | B37: O | C37: Šimečková Květoslava | E37: 14:00 - 22:00 | F37: CW_43_IMM.xlsx | G37: CW43 | H37: 15
A38: IMM | B38: N | C38: Tóth Lajos | E38: 22:00-06:00 | F38: CW_43_IMM.xlsx | G38: CW43 | H38: 15
A39: IMM | B39: R | C39: Tomšů Libuše | E39: 06:00 - 14:00 | F39: CW_43_IMM.xlsx | G39: CW43 | H39: 16
A40: IMM | B40: O | C40: Rabinský Jiří | E40: 14:00 - 22:00 | F40: CW_43_IMM.xlsx | G40: CW43 | H40: 16
A41: IMM | B41: N | C41: Molnár Melinda | E41: 22:00-06:00 | F41: CW_43_IMM.xlsx | G41: CW43 | H41: 16
A42: IMM | B42: R | C42: Štěrbová Veronika | E42: 06:00 - 14:00 | F42: CW_43_IMM.xlsx | G42: CW43 | H42: 17
A43: IMM | B43: O | C43: Staňková Anna | E43: 14:00 - 22:00 | F43: CW_43_IMM.xlsx | G43: CW43 | H43: 17
A44: IMM | B44: N | C44: Plashchevska Bohdana | E44: 22:00-06:00 | F44: CW_43_IMM.xlsx | G44: CW43 | H44: 17
A45: IMM | B45: R | C45: Rác Jozef | E45: 06:00 - 14:00 | F45: CW_43_IMM.xlsx | G45: CW43 | H45: 18
A46: IMM | B46: O | C46: Shevchuk Liudmyla | E46: 14:00 - 22:00 | F46: CW_43_IMM.xlsx | G46: CW43 | H46: 18
A47: IMM | B47: N | C47: Kovalenko Mykhailo | E47: 18:00-06:00 | F47: CW_43_IMM.xlsx | G47: CW43 | H47: 18
... A69: IMM | B69: N | C69: Lashko Tetiana | E69: 18:00-06:00 | F69: CW_43_IMM.xlsx | G69: CW43 | H69: 27
A70: SK336/W206 | B70: R | C70: Povroznik Stefan | D70: Punching | E70: 6:00 - 18:00 | F70: CW_43_SK336.xlsx | G70: CW43 | H70: 15
A71: SK336/W206 | B71: N | C71: Ciomag Gheorghe | D71: Punching | E71: 18:00 - 06:00 | F71: CW_43_SK336.xlsx | G71: CW43 | H71: 15
A72: SK336/W206 | B72: R | C72: Krysa Maria | D72: Punching | E72: 6:00 - 18:00 | F72: CW_43_SK336.xlsx | G72: CW43 | H72: 16
A73: SK336/W206 | B73: N | C73: Cretu Ana | D73: Punching | E73: 18:00 - 06:00 | F73: CW_43_SK336.xlsx | G73: CW43 | H73: 16
A74: SK336/W206 | B74: R | C74: Dzyzhak Anastasiia | D74: Milling | E74: 6:00 - 18:00 | F74: CW_43_SK336.xlsx | G74: CW43 | H74: 17
A75: SK336/W206 | B75: N | C75: Krotova Katya | D75: Milling | E75: 18:00 - 06:00 | F75: CW_43_SK336.xlsx | G75: CW43 | H75: 17
A76: SK336/W206 | B76: R | C76: Bihun Natalia | D76: Wib | E76: 6:00 - 14:00 | F76: CW_43_SK336.xlsx | G76: CW43 | H76: 18
A77: SK336/W206 | B77: N | C77: Skorina Svetlana | D77: Wib | E77: 18:00 - 06:00 | F77: CW_43_SK336.xlsx | G77: CW43 | H77: 18
A78: SK336/W206 | B78: R | C78: Hudáček Ján | D78: Us. Wel | E78: 6:00 - 14:00 | F78: CW_43_SK336.xlsx | G78: CW43 | H78: 19
A79: SK336/W206 | B79: O | C79: Shabrova Nelia | D79: Us.Wel | E79: 14:00 - 22:00 | F79: CW_43_SK336.xlsx | G79: CW43 | H79: 19
A80: SK336/W206 | B80: N | C80: Popescu Viktoriia | D80: Us.Wel | E80: 22:00 - 06:00 | F80: CW_43_SK336.xlsx | G80: CW43 | H80: 19
A81: SK336/W206 | B81: R | C81: Slashchov Viacheslav | D81: Cliping | E81: 6:00 - 18:00 | F81: CW_43_SK336.xlsx | G81: CW43 | H81: 20
... A315: G463 Prefix | B315: O | C315: Shyrshova Mariia | D315: Balení Balení | E315: 14-22 | F315: CW_43_Prefix_akrual.xlsx | G315: WEEK17 | H315: 35
